Workbook

Sheet T-All_K1 N10 P0
A1: Identifier | B1: 0 | C1: 1 | D1: 2 | E1: 3 | F1: 4 | G1: 5 | H1: 6 | I1: 7 | J1: 8 | K1: Column11 | L1: Column12
A2: 428da1312b4e9e175c8da20472e82f346f19060102702e896cd2ed510d1f82d3 | B2: 5.6707541 | C2: 2.6827083 | D2: 9.5101161 | E2: 4.1070766 | F2: 5.6419097 | G2: 4.972741 | H2: 5.3640856 | I2: 8.9479246 | J2: 7.0236156
A3: b96c0907522c2773f70c3772a20a66ed27faa11b69222bb914593d8c048e550f | B3: 7.8374335 | C3: 5.10084 | D3: 9.1046567 | E3: 4.3203477 | F3: 10.848992 | G3: 7.9346083 | H3: 5.4931447 | I3: 9.8119269 | J3: 5.5981144
A4: 91c19dd683a61988ab47f9523ac0c69189fc5bf0bc129535df465e67ceaa3f5c | B4: 6.4185382 | C4: 8.1532212 | D4: 7.9959563 | E4: 10.156819 | F4: 6.7149246 | G4: 6.3503785 | H4: 10.048271 | I4: 7.9475027 | J4: 6.9061622
A5: a77913344f83d12ba672562908a45473f0d39decfb73132ce324137df5880dca | B5: 3.6806851 | C5: 3.4622552 | D5: 7.1898996 | E5: 4.8316995 | F5: 3.4472675 | G5: 3.5914728 | H5: 7.3375266 | I5: 3.6664365 | J5: 1.5938415
A6: 31dc9a7ab1e4d4612bdaf0e2738743d8249dd2a8c694e94911c68de321218e14 | B6: 3.5151637 | C6: 4.4862471 | D6: 1.4861697 | E6: 1.3635102 | F6: 3.5352609 | G6: 3.5224217 | H6: 2.851021 | I6: 2.298538 | J6: 4.3910211
A7: cc16d76232e5a5ec88990779fb25161754f2fcae1be1817d9b06db6ed01a0252 | B7: 4.9728168 | C7: 3.8049531 | D7: 7.6249441 | E7: 7.713015 | F7: 6.2291926 | G7: 4.9568516 | H7: 7.0137946 | I7: 9.9947308 | J7: 3.6880669
A8: 6495f98496f9faa9acbcdcf4e6d7f54f0fc9d6989ccd6cbe8d514c709be1ae47 | B8: 7.4614274 | C8: 10.923784 | D8: 7.1545811 | E8: 9.045002 | F8: 4.1600031 | G8: 8.0067124 | H8: 4.6851752 | I8: 7.2636943 | J8: 4.8217605
A9: a0a4a0a999bb3c4c42ab65d8be5cc30bd395809ee6deffe8ff8849786856012c | B9: 13.601155 | C9: 12.48528 | D9: 8.0971608 | E9: 9.1003597 | F9: 9.6579612 | G9: 7.589509 | H9: 7.7401406 | I9: 8.0109913 | J9: 9.7207106
A10: 7f3b0e32ea2b17f7a0962be43fa129208723a474d1511b5ff8a21ed8c63aca65 | B10: 5.0645134 | C10: 4.9437104 | D10: 7.8400076 | E10: 9.0140865 | F10: 6.4631927 | G10: 5.7475034 | H10: 6.3928428 | I10: 3.9129451 | J10: 3.7021908
A11: 6f5b156caaebfa4130a64c596e5794c2e55be72403d2ceb5c236b43d6cf082d1 | B11: 3.5935725 | C11: 2.6608128 | D11: 3.2408391 | E11: 4.0361444 | F11: 4.4091368 | G11: 2.921721 | H11: 3.1326036 | I11: 6.0853784 | J11: 5.6636188
A12: 6aa02f42db10b522f763f840e9e8a0bcb461f6f2f570d596a768a59dbfd88113 | B12: 2.9964524 | C12: 5.5302329 | D12: 5.4020733 | E12: 3.0076945 | F12: 3.5713605 | G12: 3.2493069 | H12: 1.746399 | I12: 9.1793924 | J12: 1.741344
A13: f3cc524e5f2cc476c53eea535c2fc45073cef06fbd25ecd7e5fe92d8b87b3d29 | B13: 4.0426867 | C13: 4.8664889 | D13: 3.1202477 | E13: 6.2967995 | F13: 6.7149012 | G13: 4.2320073 | H13: 1.4793517 | I13: 4.1640665 | J13: 3.1298041

Sheet R Squared
A1: Identifier | B1: 0 | C1: 1 | D1: 2 | E1: 3 | F1: 4 | G1: 5 | H1: 6 | I1: 7 | J1: 8 | L1: R Squared
A2: =T_All_K1_N10_P0[[#This Row],[Identifier]] -> 428da1312b4e9e175c8da20472e82f346f19060102702e896cd2ed510d1f82d3 | B2: =T_All_K1_N10_P0[[#This Row],[0]] -> 5.6707541 | C2: =T_All_K1_N10_P0[[#This Row],[1]] -> 2.6827083 | D2: =T_All_K1_N10_P0[[#This Row],[2]] -> 9.5101161 | E2: =T_All_K1_N10_P0[[#This Row],[3]] -> 4.1070766 | F2: =T_All_K1_N10_P0[[#This Row],[4]] -> 5.6419097 | G2: =T_All_K1_N10_P0[[#This Row],[5]] -> 4.972741 | H2: =T_All_K1_N10_P0[[#This Row],[6]] -> 5.3640856 | I2: =T_All_K1_N10_P0[[#This Row],[7]] -> 8.9479246 | J2: =T_All_K1_N10_P0[[#This Row],[8]] -> 7.0236156 | L2: =RSQ(B2:J2,$B$1:$J$1) -> 0.12240314
A3: =T_All_K1_N10_P0[[#This Row],[Identifier]] -> b96c0907522c2773f70c3772a20a66ed27faa11b69222bb914593d8c048e550f | B3: =T_All_K1_N10_P0[[#This Row],[0]] -> 7.8374335 | C3: =T_All_K1_N10_P0[[#This Row],[1]] -> 5.10084 | D3: =T_All_K1_N10_P0[[#This Row],[2]] -> 9.1046567 | E3: =T_All_K1_N10_P0[[#This Row],[3]] -> 4.3203477 | F3: =T_All_K1_N10_P0[[#This Row],[4]] -> 10.848992 | G3: =T_All_K1_N10_P0[[#This Row],[5]] -> 7.9346083 | H3: =T_All_K1_N10_P0[[#This Row],[6]] -> 5.4931447 | I3: =T_All_K1_N10_P0[[#This Row],[7]] -> 9.8119269 | J3: =T_All_K1_N10_P0[[#This Row],[8]] -> 5.5981144 | L3: =RSQ(B3:J3,$B$1:$J$1) -> 0.00095834561
A4: =T_All_K1_N10_P0[[#This Row],[Identifier]] -> 91c19dd683a61988ab47f9523ac0c69189fc5bf0bc129535df465e67ceaa3f5c | B4: =T_All_K1_N10_P0[[#This Row],[0]] -> 6.4185382 | C4: =T_All_K1_N10_P0[[#This Row],[1]] -> 8.1532212 | D4: =T_All_K1_N10_P0[[#This Row],[2]] -> 7.9959563 | E4: =T_All_K1_N10_P0[[#This Row],[3]] -> 10.156819 | F4: =T_All_K1_N10_P0[[#This Row],[4]] -> 6.7149246 | G4: =T_All_K1_N10_P0[[#This Row],[5]] -> 6.3503785 | H4: =T_All_K1_N10_P0[[#This Row],[6]] -> 10.048271 | I4: =T_All_K1_N10_P0[[#This Row],[7]] -> 7.9475027 | J4: =T_All_K1_N10_P0[[#This Row],[8]] -> 6.9061622 | L4: =RSQ(B4:J4,$B$1:$J$1) -> 0.0026480824
A5: =T_All_K1_N10_P0[[#This Row],[Identifier]] -> a77913344f83d12ba672562908a45473f0d39decfb73132ce324137df5880dca | B5: =T_All_K1_N10_P0[[#This Row],[0]] -> 3.6806851 | C5: =T_All_K1_N10_P0[[#This Row],[1]] -> 3.4622552 | D5: =T_All_K1_N10_P0[[#This Row],[2]] -> 7.1898996 | E5: =T_All_K1_N10_P0[[#This Row],[3]] -> 4.8316995 | F5: =T_All_K1_N10_P0[[#This Row],[4]] -> 3.4472675 | G5: =T_All_K1_N10_P0[[#This Row],[5]] -> 3.5914728 | H5: =T_All_K1_N10_P0[[#This Row],[6]] -> 7.3375266 | I5: =T_All_K1_N10_P0[[#This Row],[7]] -> 3.6664365 | J5: =T_All_K1_N10_P0[[#This Row],[8]] -> 1.5938415 | L5: =RSQ(B5:J5,$B$1:$J$1) -> 0.045007168
A6: =T_All_K1_N10_P0[[#This Row],[Identifier]] -> 31dc9a7ab1e4d4612bdaf0e2738743d8249dd2a8c694e94911c68de321218e14 | B6: =T_All_K1_N10_P0[[#This Row],[0]] -> 3.5151637 | C6: =T_All_K1_N10_P0[[#This Row],[1]] -> 4.4862471 | D6: =T_All_K1_N10_P0[[#This Row],[2]] -> 1.4861697 | E6: =T_All_K1_N10_P0[[#This Row],[3]] -> 1.3635102 | F6: =T_All_K1_N10_P0[[#This Row],[4]] -> 3.5352609 | G6: =T_All_K1_N10_P0[[#This Row],[5]] -> 3.5224217 | H6: =T_All_K1_N10_P0[[#This Row],[6]] -> 2.851021 | I6: =T_All_K1_N10_P0[[#This Row],[7]] -> 2.298538 | J6: =T_All_K1_N10_P0[[#This Row],[8]] -> 4.3910211 | L6: =RSQ(B6:J6,$B$1:$J$1) -> 0.0053449103
A7: =T_All_K1_N10_P0[[#This Row],[Identifier]] -> cc16d76232e5a5ec88990779fb25161754f2fcae1be1817d9b06db6ed01a0252 | B7: =T_All_K1_N10_P0[[#This Row],[0]] -> 4.9728168 | C7: =T_All_K1_N10_P0[[#This Row],[1]] -> 3.8049531 | D7: =T_All_K1_N10_P0[[#This Row],[2]] -> 7.6249441 | E7: =T_All_K1_N10_P0[[#This Row],[3]] -> 7.713015 | F7: =T_All_K1_N10_P0[[#This Row],[4]] -> 6.2291926 | G7: =T_All_K1_N10_P0[[#This Row],[5]] -> 4.9568516 | H7: =T_All_K1_N10_P0[[#This Row],[6]] -> 7.0137946 | I7: =T_All_K1_N10_P0[[#This Row],[7]] -> 9.9947308 | J7: =T_All_K1_N10_P0[[#This Row],[8]] -> 3.6880669 | L7: =RSQ(B7:J7,$B$1:$J$1) -> 0.043188611
A8: =T_All_K1_N10_P0[[#This Row],[Identifier]] -> 6495f98496f9faa9acbcdcf4e6d7f54f0fc9d6989ccd6cbe8d514c709be1ae47 | B8: =T_All_K1_N10_P0[[#This Row],[0]] -> 7.4614274 | C8: =T_All_K1_N10_P0[[#This Row],[1]] -> 10.923784 | D8: =T_All_K1_N10_P0[[#This Row],[2]] -> 7.1545811 | E8: =T_All_K1_N10_P0[[#This Row],[3]] -> 9.045002 | F8: =T_All_K1_N10_P0[[#This Row],[4]] -> 4.1600031 | G8: =T_All_K1_N10_P0[[#This Row],[5]] -> 8.0067124 | H8: =T_All_K1_N10_P0[[#This Row],[6]] -> 4.6851752 | I8: =T_All_K1_N10_P0[[#This Row],[7]] -> 7.2636943 | J8: =T_All_K1_N10_P0[[#This Row],[8]] -> 4.8217605 | L8: =RSQ(B8:J8,$B$1:$J$1) -> 0.32325944
A9: =T_All_K1_N10_P0[[#This Row],[Identifier]] -> a0a4a0a999bb3c4c42ab65d8be5cc30bd395809ee6deffe8ff8849786856012c | B9: =T_All_K1_N10_P0[[#This Row],[0]] -> 13.601155 | C9: =T_All_K1_N10_P0[[#This Row],[1]] -> 12.48528 | D9: =T_All_K1_N10_P0[[#This Row],[2]] -> 8.0971608 | E9: =T_All_K1_N10_P0[[#This Row],[3]] -> 9.1003597 | F9: =T_All_K1_N10_P0[[#This Row],[4]] -> 9.6579612 | G9: =T_All_K1_N10_P0[[#This Row],[5]] -> 7.589509 | H9: =T_All_K1_N10_P0[[#This Row],[6]] -> 7.7401406 | I9: =T_All_K1_N10_P0[[#This Row],[7]] -> 8.0109913 | J9: =T_All_K1_N10_P0[[#This Row],[8]] -> 9.7207106 | L9: =RSQ(B9:J9,$B$1:$J$1) -> 0.43918803
A10: =T_All_K1_N10_P0[[#This Row],[Identifier]] -> 7f3b0e32ea2b17f7a0962be43fa129208723a474d1511b5ff8a21ed8c63aca65 | B10: =T_All_K1_N10_P0[[#This Row],[0]] -> 5.0645134 | C10: =T_All_K1_N10_P0[[#This Row],[1]] -> 4.9437104 | D10: =T_All_K1_N10_P0[[#This Row],[2]] -> 7.8400076 | E10: =T_All_K1_N10_P0[[#This Row],[3]] -> 9.0140865 | F10: =T_All_K1_N10_P0[[#This Row],[4]] -> 6.4631927 | G10: =T_All_K1_N10_P0[[#This Row],[5]] -> 5.7475034 | H10: =T_All_K1_N10_P0[[#This Row],[6]] -> 6.3928428 | I10: =T_All_K1_N10_P0[[#This Row],[7]] -> 3.9129451 | J10: =T_All_K1_N10_P0[[#This Row],[8]] -> 3.7021908 | L10: =RSQ(B10:J10,$B$1:$J$1) -> 0.14743669
A11: =T_All_K1_N10_P0[[#This Row],[Identifier]] -> 6f5b156caaebfa4130a64c596e5794c2e55be72403d2ceb5c236b43d6cf082d1 | B11: =T_All_K1_N10_P0[[#This Row],[0]] -> 3.5935725 | C11: =T_All_K1_N10_P0[[#This Row],[1]] -> 2.6608128 | D11: =T_All_K1_N10_P0[[#This Row],[2]] -> 3.2408391 | E11: =T_All_K1_N10_P0[[#This Row],[3]] -> 4.0361444 | F11: =T_All_K1_N10_P0[[#This Row],[4]] -> 4.4091368 | G11: =T_All_K1_N10_P0[[#This Row],[5]] -> 2.921721 | H11: =T_All_K1_N10_P0[[#This Row],[6]] -> 3.1326036 | I11: =T_All_K1_N10_P0[[#This Row],[7]] -> 6.0853784 | J11: =T_All_K1_N10_P0[[#This Row],[8]] -> 5.6636188 | L11: =RSQ(B11:J11,$B$1:$J$1) -> 0.42154895
A12: =T_All_K1_N10_P0[[#This Row],[Identifier]] -> 6aa02f42db10b522f763f840e9e8a0bcb461f6f2f570d596a768a59dbfd88113 | B12: =T_All_K1_N10_P0[[#This Row],[0]] -> 2.9964524 | C12: =T_All_K1_N10_P0[[#This Row],[1]] -> 5.5302329 | D12: =T_All_K1_N10_P0[[#This Row],[2]] -> 5.4020733 | E12: =T_All_K1_N10_P0[[#This Row],[3]] -> 3.0076945 | F12: =T_All_K1_N10_P0[[#This Row],[4]] -> 3.5713605 | G12: =T_All_K1_N10_P0[[#This Row],[5]] -> 3.2493069 | H12: =T_All_K1_N10_P0[[#This Row],[6]] -> 1.746399 | I12: =T_All_K1_N10_P0[[#This Row],[7]] -> 9.1793924 | J12: =T_All_K1_N10_P0[[#This Row],[8]] -> 1.741344 | L12: =RSQ(B12:J12,$B$1:$J$1) -> 0.00049423108
A13: =T_All_K1_N10_P0[[#This Row],[Identifier]] -> f3cc524e5f2cc476c53eea535c2fc45073cef06fbd25ecd7e5fe92d8b87b3d29 | B13: =T_All_K1_N10_P0[[#This Row],[0]] -> 4.0426867 | C13: =T_All_K1_N10_P0[[#This Row],[1]] -> 4.8664889 | D13: =T_All_K1_N10_P0[[#This Row],[2]] -> 3.1202477 | E13: =T_All_K1_N10_P0[[#This Row],[3]] -> 6.2967995 | F13: =T_All_K1_N10_P0[[#This Row],[4]] -> 6.7149012 | G13: =T_All_K1_N10_P0[[#This Row],[5]] -> 4.2320073 | H13: =T_All_K1_N10_P0[[#This Row],[6]] -> 1.4793517 | I13: =T_All_K1_N10_P0[[#This Row],[7]] -> 4.1640665 | J13: =T_All_K1_N10_P0[[#This Row],[8]] -> 3.1298041 | L13: =RSQ(B13:J13,$B$1:$J$1) -> 0.098353899
K16: Ave RSQ | L16: =AVERAGE(L2:L13) -> 0.13748596
L19: RSQ of Ave
A20: T Averages | B20: =AVERAGE(B2:B13) -> 5.7379332 | C20: =AVERAGE(C2:C13) -> 5.7583778 | D20: =AVERAGE(D2:D13) -> 6.4805543 | E20: =AVERAGE(E2:E13) -> 6.0827129 | F20: =AVERAGE(F2:F13) -> 5.9495086 | G20: =AVERAGE(G2:G13) -> 5.2562695 | H20: =AVERAGE(H2:H13) -> 5.2736963 | I20: =AVERAGE(I2:I13) -> 6.7736273 | J20: =AVERAGE(J2:J13) -> 4.8316875 | L20: =RSQ(B1:J1,B20:J20) -> 0.080270097
J41: s

Sheet Relative Change
A1: ID | B1: 0-1 | C1: 1-2 | D1: 2-3 | E1: 3-4 | F1: 4-5 | G1: 5-6 | H1: 6-7 | I1: 7-8 | K1: Average per ID | L1: Max-Min
A2: =T_All_K1_N10_P0[[#This Row],[Identifier]] -> 428da1312b4e9e175c8da20472e82f346f19060102702e896cd2ed510d1f82d3 | B2: =(T_All_K1_N10_P0[[#This Row],[1]]-T_All_K1_N10_P0[[#This Row],[0]])/ABS(T_All_K1_N10_P0[[#This Row],[0]]) -> -0.52692212 | C2: =(T_All_K1_N10_P0[[#This Row],[2]]-T_All_K1_N10_P0[[#This Row],[1]])/ABS(T_All_K1_N10_P0[[#This Row],[1]]) -> 2.5449683 | D2: =(T_All_K1_N10_P0[[#This Row],[3]]-T_All_K1_N10_P0[[#This Row],[2]])/ABS(T_All_K1_N10_P0[[#This Row],[2]]) -> -0.56813601 | E2: =(T_All_K1_N10_P0[[#This Row],[4]]-T_All_K1_N10_P0[[#This Row],[3]])/ABS(T_All_K1_N10_P0[[#This Row],[3]]) -> 0.3737045 | F2: =(T_All_K1_N10_P0[[#This Row],[5]]-T_All_K1_N10_P0[[#This Row],[4]])/ABS(T_All_K1_N10_P0[[#This Row],[4]]) -> -0.11860676 | G2: =(T_All_K1_N10_P0[[#This Row],[6]]-T_All_K1_N10_P0[[#This Row],[5]])/ABS(T_All_K1_N10_P0[[#This Row],[5]]) -> 0.078697959 | H2: =(T_All_K1_N10_P0[[#This Row],[7]]-T_All_K1_N10_P0[[#This Row],[6]])/ABS(T_All_K1_N10_P0[[#This Row],[6]]) -> 0.66811741 | I2: =(T_All_K1_N10_P0[[#This Row],[8]]-T_All_K1_N10_P0[[#This Row],[7]])/ABS(T_All_K1_N10_P0[[#This Row],[7]]) -> -0.21505646 | K2: =AVERAGE(B2:I2) -> 0.27959586 | L2: =(T_All_K1_N10_P0[[#This Row],[8]]-T_All_K1_N10_P0[[#This Row],[0]])/ABS(T_All_K1_N10_P0[[#This Row],[0]]) -> 0.23856819
A3: =T_All_K1_N10_P0[[#This Row],[Identifier]] -> b96c0907522c2773f70c3772a20a66ed27faa11b69222bb914593d8c048e550f | B3: =(T_All_K1_N10_P0[[#This Row],[1]]-T_All_K1_N10_P0[[#This Row],[0]])/ABS(T_All_K1_N10_P0[[#This Row],[0]]) -> -0.3491696 | C3: =(T_All_K1_N10_P0[[#This Row],[2]]-T_All_K1_N10_P0[[#This Row],[1]])/ABS(T_All_K1_N10_P0[[#This Row],[1]]) -> 0.78493283 | D3: =(T_All_K1_N10_P0[[#This Row],[3]]-T_All_K1_N10_P0[[#This Row],[2]])/ABS(T_All_K1_N10_P0[[#This Row],[2]]) -> -0.52547935 | E3: =(T_All_K1_N10_P0[[#This Row],[4]]-T_All_K1_N10_P0[[#This Row],[3]])/ABS(T_All_K1_N10_P0[[#This Row],[3]]) -> 1.5111387 | F3: =(T_All_K1_N10_P0[[#This Row],[5]]-T_All_K1_N10_P0[[#This Row],[4]])/ABS(T_All_K1_N10_P0[[#This Row],[4]]) -> -0.26863178 | G3: =(T_All_K1_N10_P0[[#This Row],[6]]-T_All_K1_N10_P0[[#This Row],[5]])/ABS(T_All_K1_N10_P0[[#This Row],[5]]) -> -0.30769806 | H3: =(T_All_K1_N10_P0[[#This Row],[7]]-T_All_K1_N10_P0[[#This Row],[6]])/ABS(T_All_K1_N10_P0[[#This Row],[6]]) -> 0.78621309 | I3: =(T_All_K1_N10_P0[[#This Row],[8]]-T_All_K1_N10_P0[[#This Row],[7]])/ABS(T_All_K1_N10_P0[[#This Row],[7]]) -> -0.4294582 | K3: =AVERAGE(B3:I3) -> 0.15023096 | L3: =(T_All_K1_N10_P0[[#This Row],[8]]-T_All_K1_N10_P0[[#This Row],[0]])/ABS(T_All_K1_N10_P0[[#This Row],[0]]) -> -0.28572098
A4: =T_All_K1_N10_P0[[#This Row],[Identifier]] -> 91c19dd683a61988ab47f9523ac0c69189fc5bf0bc129535df465e67ceaa3f5c | B4: =(T_All_K1_N10_P0[[#This Row],[1]]-T_All_K1_N10_P0[[#This Row],[0]])/ABS(T_All_K1_N10_P0[[#This Row],[0]]) -> 0.27026137 | C4: =(T_All_K1_N10_P0[[#This Row],[2]]-T_All_K1_N10_P0[[#This Row],[1]])/ABS(T_All_K1_N10_P0[[#This Row],[1]]) -> -0.019288685 | D4: =(T_All_K1_N10_P0[[#This Row],[3]]-T_All_K1_N10_P0[[#This Row],[2]])/ABS(T_All_K1_N10_P0[[#This Row],[2]]) -> 0.27024449 | E4: =(T_All_K1_N10_P0[[#This Row],[4]]-T_All_K1_N10_P0[[#This Row],[3]])/ABS(T_All_K1_N10_P0[[#This Row],[3]]) -> -0.33887526 | F4: =(T_All_K1_N10_P0[[#This Row],[5]]-T_All_K1_N10_P0[[#This Row],[4]])/ABS(T_All_K1_N10_P0[[#This Row],[4]]) -> -0.05428894 | G4: =(T_All_K1_N10_P0[[#This Row],[6]]-T_All_K1_N10_P0[[#This Row],[5]])/ABS(T_All_K1_N10_P0[[#This Row],[5]]) -> 0.58231054 | H4: =(T_All_K1_N10_P0[[#This Row],[7]]-T_All_K1_N10_P0[[#This Row],[6]])/ABS(T_All_K1_N10_P0[[#This Row],[6]]) -> -0.20906762 | I4: =(T_All_K1_N10_P0[[#This Row],[8]]-T_All_K1_N10_P0[[#This Row],[7]])/ABS(T_All_K1_N10_P0[[#This Row],[7]]) -> -0.13102739 | K4: =AVERAGE(B4:I4) -> 0.046283564 | L4: =(T_All_K1_N10_P0[[#This Row],[8]]-T_All_K1_N10_P0[[#This Row],[0]])/ABS(T_All_K1_N10_P0[[#This Row],[0]]) -> 0.075971186
A5: =T_All_K1_N10_P0[[#This Row],[Identifier]] -> a77913344f83d12ba672562908a45473f0d39decfb73132ce324137df5880dca | B5: =(T_All_K1_N10_P0[[#This Row],[1]]-T_All_K1_N10_P0[[#This Row],[0]])/ABS(T_All_K1_N10_P0[[#This Row],[0]]) -> -0.059344885 | C5: =(T_All_K1_N10_P0[[#This Row],[2]]-T_All_K1_N10_P0[[#This Row],[1]])/ABS(T_All_K1_N10_P0[[#This Row],[1]]) -> 1.0766521 | D5: =(T_All_K1_N10_P0[[#This Row],[3]]-T_All_K1_N10_P0[[#This Row],[2]])/ABS(T_All_K1_N10_P0[[#This Row],[2]]) -> -0.3279879 | E5: =(T_All_K1_N10_P0[[#This Row],[4]]-T_All_K1_N10_P0[[#This Row],[3]])/ABS(T_All_K1_N10_P0[[#This Row],[3]]) -> -0.28653106 | F5: =(T_All_K1_N10_P0[[#This Row],[5]]-T_All_K1_N10_P0[[#This Row],[4]])/ABS(T_All_K1_N10_P0[[#This Row],[4]]) -> 0.041831763 | G5: =(T_All_K1_N10_P0[[#This Row],[6]]-T_All_K1_N10_P0[[#This Row],[5]])/ABS(T_All_K1_N10_P0[[#This Row],[5]]) -> 1.0430411 | H5: =(T_All_K1_N10_P0[[#This Row],[7]]-T_All_K1_N10_P0[[#This Row],[6]])/ABS(T_All_K1_N10_P0[[#This Row],[6]]) -> -0.5003171 | I5: =(T_All_K1_N10_P0[[#This Row],[8]]-T_All_K1_N10_P0[[#This Row],[7]])/ABS(T_All_K1_N10_P0[[#This Row],[7]]) -> -0.56528868 | K5: =AVERAGE(B5:I5) -> 0.052756918 | L5: =(T_All_K1_N10_P0[[#This Row],[8]]-T_All_K1_N10_P0[[#This Row],[0]])/ABS(T_All_K1_N10_P0[[#This Row],[0]]) -> -0.56697152
A6: =T_All_K1_N10_P0[[#This Row],[Identifier]] -> 31dc9a7ab1e4d4612bdaf0e2738743d8249dd2a8c694e94911c68de321218e14 | B6: =(T_All_K1_N10_P0[[#This Row],[1]]-T_All_K1_N10_P0[[#This Row],[0]])/ABS(T_All_K1_N10_P0[[#This Row],[0]]) -> 0.27625555 | C6: =(T_All_K1_N10_P0[[#This Row],[2]]-T_All_K1_N10_P0[[#This Row],[1]])/ABS(T_All_K1_N10_P0[[#This Row],[1]]) -> -0.66872762 | D6: =(T_All_K1_N10_P0[[#This Row],[3]]-T_All_K1_N10_P0[[#This Row],[2]])/ABS(T_All_K1_N10_P0[[#This Row],[2]]) -> -0.08253403 | E6: =(T_All_K1_N10_P0[[#This Row],[4]]-T_All_K1_N10_P0[[#This Row],[3]])/ABS(T_All_K1_N10_P0[[#This Row],[3]]) -> 1.5927646 | F6: =(T_All_K1_N10_P0[[#This Row],[5]]-T_All_K1_N10_P0[[#This Row],[4]])/ABS(T_All_K1_N10_P0[[#This Row],[4]]) -> -0.003631747 | G6: =(T_All_K1_N10_P0[[#This Row],[6]]-T_All_K1_N10_P0[[#This Row],[5]])/ABS(T_All_K1_N10_P0[[#This Row],[5]]) -> -0.19060771 | H6: =(T_All_K1_N10_P0[[#This Row],[7]]-T_All_K1_N10_P0[[#This Row],[6]])/ABS(T_All_K1_N10_P0[[#This Row],[6]]) -> -0.19378427 | I6: =(T_All_K1_N10_P0[[#This Row],[8]]-T_All_K1_N10_P0[[#This Row],[7]])/ABS(T_All_K1_N10_P0[[#This Row],[7]]) -> 0.91035396 | K6: =AVERAGE(B6:I6) -> 0.20501109 | L6: =(T_All_K1_N10_P0[[#This Row],[8]]-T_All_K1_N10_P0[[#This Row],[0]])/ABS(T_All_K1_N10_P0[[#This Row],[0]]) -> 0.24916548
A7: =T_All_K1_N10_P0[[#This Row],[Identifier]] -> cc16d76232e5a5ec88990779fb25161754f2fcae1be1817d9b06db6ed01a0252 | B7: =(T_All_K1_N10_P0[[#This Row],[1]]-T_All_K1_N10_P0[[#This Row],[0]])/ABS(T_All_K1_N10_P0[[#This Row],[0]]) -> -0.23484953 | C7: =(T_All_K1_N10_P0[[#This Row],[2]]-T_All_K1_N10_P0[[#This Row],[1]])/ABS(T_All_K1_N10_P0[[#This Row],[1]]) -> 1.0039522 | D7: =(T_All_K1_N10_P0[[#This Row],[3]]-T_All_K1_N10_P0[[#This Row],[2]])/ABS(T_All_K1_N10_P0[[#This Row],[2]]) -> 0.011550369 | E7: =(T_All_K1_N10_P0[[#This Row],[4]]-T_All_K1_N10_P0[[#This Row],[3]])/ABS(T_All_K1_N10_P0[[#This Row],[3]]) -> -0.19237903 | F7: =(T_All_K1_N10_P0[[#This Row],[5]]-T_All_K1_N10_P0[[#This Row],[4]])/ABS(T_All_K1_N10_P0[[#This Row],[4]]) -> -0.20425456 | G7: =(T_All_K1_N10_P0[[#This Row],[6]]-T_All_K1_N10_P0[[#This Row],[5]])/ABS(T_All_K1_N10_P0[[#This Row],[5]]) -> 0.41496965 | H7: =(T_All_K1_N10_P0[[#This Row],[7]]-T_All_K1_N10_P0[[#This Row],[6]])/ABS(T_All_K1_N10_P0[[#This Row],[6]]) -> 0.42501048 | I7: =(T_All_K1_N10_P0[[#This Row],[8]]-T_All_K1_N10_P0[[#This Row],[7]])/ABS(T_All_K1_N10_P0[[#This Row],[7]]) -> -0.63099888 | K7: =AVERAGE(B7:I7) -> 0.074125083 | L7: =(T_All_K1_N10_P0[[#This Row],[8]]-T_All_K1_N10_P0[[#This Row],[0]])/ABS(T_All_K1_N10_P0[[#This Row],[0]]) -> -0.25835457
A8: =T_All_K1_N10_P0[[#This Row],[Identifier]] -> 6495f98496f9faa9acbcdcf4e6d7f54f0fc9d6989ccd6cbe8d514c709be1ae47 | B8: =(T_All_K1_N10_P0[[#This Row],[1]]-T_All_K1_N10_P0[[#This Row],[0]])/ABS(T_All_K1_N10_P0[[#This Row],[0]]) -> 0.46403405 | C8: =(T_All_K1_N10_P0[[#This Row],[2]]-T_All_K1_N10_P0[[#This Row],[1]])/ABS(T_All_K1_N10_P0[[#This Row],[1]]) -> -0.34504552 | D8: =(T_All_K1_N10_P0[[#This Row],[3]]-T_All_K1_N10_P0[[#This Row],[2]])/ABS(T_All_K1_N10_P0[[#This Row],[2]]) -> 0.26422524 | E8: =(T_All_K1_N10_P0[[#This Row],[4]]-T_All_K1_N10_P0[[#This Row],[3]])/ABS(T_All_K1_N10_P0[[#This Row],[3]]) -> -0.54007715 | F8: =(T_All_K1_N10_P0[[#This Row],[5]]-T_All_K1_N10_P0[[#This Row],[4]])/ABS(T_All_K1_N10_P0[[#This Row],[4]]) -> 0.92468907 | G8: =(T_All_K1_N10_P0[[#This Row],[6]]-T_All_K1_N10_P0[[#This Row],[5]])/ABS(T_All_K1_N10_P0[[#This Row],[5]]) -> -0.41484408 | H8: =(T_All_K1_N10_P0[[#This Row],[7]]-T_All_K1_N10_P0[[#This Row],[6]])/ABS(T_All_K1_N10_P0[[#This Row],[6]]) -> 0.55035703 | I8: =(T_All_K1_N10_P0[[#This Row],[8]]-T_All_K1_N10_P0[[#This Row],[7]])/ABS(T_All_K1_N10_P0[[#This Row],[7]]) -> -0.33618344 | K8: =AVERAGE(B8:I8) -> 0.0708944 | L8: =(T_All_K1_N10_P0[[#This Row],[8]]-T_All_K1_N10_P0[[#This Row],[0]])/ABS(T_All_K1_N10_P0[[#This Row],[0]]) -> -0.35377505
A9: =T_All_K1_N10_P0[[#This Row],[Identifier]] -> a0a4a0a999bb3c4c42ab65d8be5cc30bd395809ee6deffe8ff8849786856012c | B9: =(T_All_K1_N10_P0[[#This Row],[1]]-T_All_K1_N10_P0[[#This Row],[0]])/ABS(T_All_K1_N10_P0[[#This Row],[0]]) -> -0.082042641 | C9: =(T_All_K1_N10_P0[[#This Row],[2]]-T_All_K1_N10_P0[[#This Row],[1]])/ABS(T_All_K1_N10_P0[[#This Row],[1]]) -> -0.35146342 | D9: =(T_All_K1_N10_P0[[#This Row],[3]]-T_All_K1_N10_P0[[#This Row],[2]])/ABS(T_All_K1_N10_P0[[#This Row],[2]]) -> 0.12389514 | E9: =(T_All_K1_N10_P0[[#This Row],[4]]-T_All_K1_N10_P0[[#This Row],[3]])/ABS(T_All_K1_N10_P0[[#This Row],[3]]) -> 0.061272471 | F9: =(T_All_K1_N10_P0[[#This Row],[5]]-T_All_K1_N10_P0[[#This Row],[4]])/ABS(T_All_K1_N10_P0[[#This Row],[4]]) -> -0.21417069 | G9: =(T_All_K1_N10_P0[[#This Row],[6]]-T_All_K1_N10_P0[[#This Row],[5]])/ABS(T_All_K1_N10_P0[[#This Row],[5]]) -> 0.019847344 | H9: =(T_All_K1_N10_P0[[#This Row],[7]]-T_All_K1_N10_P0[[#This Row],[6]])/ABS(T_All_K1_N10_P0[[#This Row],[6]]) -> 0.034992998 | I9: =(T_All_K1_N10_P0[[#This Row],[8]]-T_All_K1_N10_P0[[#This Row],[7]])/ABS(T_All_K1_N10_P0[[#This Row],[7]]) -> 0.21342168 | K9: =AVERAGE(B9:I9) -> -0.024280888 | L9: =(T_All_K1_N10_P0[[#This Row],[8]]-T_All_K1_N10_P0[[#This Row],[0]])/ABS(T_All_K1_N10_P0[[#This Row],[0]]) -> -0.28530254
A10: =T_All_K1_N10_P0[[#This Row],[Identifier]] -> 7f3b0e32ea2b17f7a0962be43fa129208723a474d1511b5ff8a21ed8c63aca65 | B10: =(T_All_K1_N10_P0[[#This Row],[1]]-T_All_K1_N10_P0[[#This Row],[0]])/ABS(T_All_K1_N10_P0[[#This Row],[0]]) -> -0.023852845 | C10: =(T_All_K1_N10_P0[[#This Row],[2]]-T_All_K1_N10_P0[[#This Row],[1]])/ABS(T_All_K1_N10_P0[[#This Row],[1]]) -> 0.58585496 | D10: =(T_All_K1_N10_P0[[#This Row],[3]]-T_All_K1_N10_P0[[#This Row],[2]])/ABS(T_All_K1_N10_P0[[#This Row],[2]]) -> 0.14975481 | E10: =(T_All_K1_N10_P0[[#This Row],[4]]-T_All_K1_N10_P0[[#This Row],[3]])/ABS(T_All_K1_N10_P0[[#This Row],[3]]) -> -0.28298971 | F10: =(T_All_K1_N10_P0[[#This Row],[5]]-T_All_K1_N10_P0[[#This Row],[4]])/ABS(T_All_K1_N10_P0[[#This Row],[4]]) -> -0.1107331 | G10: =(T_All_K1_N10_P0[[#This Row],[6]]-T_All_K1_N10_P0[[#This Row],[5]])/ABS(T_All_K1_N10_P0[[#This Row],[5]]) -> 0.11228169 | H10: =(T_All_K1_N10_P0[[#This Row],[7]]-T_All_K1_N10_P0[[#This Row],[6]])/ABS(T_All_K1_N10_P0[[#This Row],[6]]) -> -0.38791783 | I10: =(T_All_K1_N10_P0[[#This Row],[8]]-T_All_K1_N10_P0[[#This Row],[7]])/ABS(T_All_K1_N10_P0[[#This Row],[7]]) -> -0.053860784 | K10: =AVERAGE(B10:I10) -> -0.0014328502 | L10: =(T_All_K1_N10_P0[[#This Row],[8]]-T_All_K1_N10_P0[[#This Row],[0]])/ABS(T_All_K1_N10_P0[[#This Row],[0]]) -> -0.26899378
A11: =T_All_K1_N10_P0[[#This Row],[Identifier]] -> 6f5b156caaebfa4130a64c596e5794c2e55be72403d2ceb5c236b43d6cf082d1 | B11: =(T_All_K1_N10_P0[[#This Row],[1]]-T_All_K1_N10_P0[[#This Row],[0]])/ABS(T_All_K1_N10_P0[[#This Row],[0]]) -> -0.25956333 | C11: =(T_All_K1_N10_P0[[#This Row],[2]]-T_All_K1_N10_P0[[#This Row],[1]])/ABS(T_All_K1_N10_P0[[#This Row],[1]]) -> 0.21798837 | D11: =(T_All_K1_N10_P0[[#This Row],[3]]-T_All_K1_N10_P0[[#This Row],[2]])/ABS(T_All_K1_N10_P0[[#This Row],[2]]) -> 0.24540106 | E11: =(T_All_K1_N10_P0[[#This Row],[4]]-T_All_K1_N10_P0[[#This Row],[3]])/ABS(T_All_K1_N10_P0[[#This Row],[3]]) -> 0.092413041 | F11: =(T_All_K1_N10_P0[[#This Row],[5]]-T_All_K1_N10_P0[[#This Row],[4]])/ABS(T_All_K1_N10_P0[[#This Row],[4]]) -> -0.33734853 | G11: =(T_All_K1_N10_P0[[#This Row],[6]]-T_All_K1_N10_P0[[#This Row],[5]])/ABS(T_All_K1_N10_P0[[#This Row],[5]]) -> 0.072177517 | H11: =(T_All_K1_N10_P0[[#This Row],[7]]-T_All_K1_N10_P0[[#This Row],[6]])/ABS(T_All_K1_N10_P0[[#This Row],[6]]) -> 0.94259447 | I11: =(T_All_K1_N10_P0[[#This Row],[8]]-T_All_K1_N10_P0[[#This Row],[7]])/ABS(T_All_K1_N10_P0[[#This Row],[7]]) -> -0.069307039 | K11: =AVERAGE(B11:I11) -> 0.11304444 | L11: =(T_All_K1_N10_P0[[#This Row],[8]]-T_All_K1_N10_P0[[#This Row],[0]])/ABS(T_All_K1_N10_P0[[#This Row],[0]]) -> 0.57604135
A12: =T_All_K1_N10_P0[[#This Row],[Identifier]] -> 6aa02f42db10b522f763f840e9e8a0bcb461f6f2f570d596a768a59dbfd88113 | B12: =(T_All_K1_N10_P0[[#This Row],[1]]-T_All_K1_N10_P0[[#This Row],[0]])/ABS(T_All_K1_N10_P0[[#This Row],[0]]) -> 0.84559346 | C12: =(T_All_K1_N10_P0[[#This Row],[2]]-T_All_K1_N10_P0[[#This Row],[1]])/ABS(T_All_K1_N10_P0[[#This Row],[1]]) -> -0.023174359 | D12: =(T_All_K1_N10_P0[[#This Row],[3]]-T_All_K1_N10_P0[[#This Row],[2]])/ABS(T_All_K1_N10_P0[[#This Row],[2]]) -> -0.44323331 | E12: =(T_All_K1_N10_P0[[#This Row],[4]]-T_All_K1_N10_P0[[#This Row],[3]])/ABS(T_All_K1_N10_P0[[#This Row],[3]]) -> 0.18740802 | F12: =(T_All_K1_N10_P0[[#This Row],[5]]-T_All_K1_N10_P0[[#This Row],[4]])/ABS(T_All_K1_N10_P0[[#This Row],[4]]) -> -0.090176725 | G12: =(T_All_K1_N10_P0[[#This Row],[6]]-T_All_K1_N10_P0[[#This Row],[5]])/ABS(T_All_K1_N10_P0[[#This Row],[5]]) -> -0.46253185 | H12: =(T_All_K1_N10_P0[[#This Row],[7]]-T_All_K1_N10_P0[[#This Row],[6]])/ABS(T_All_K1_N10_P0[[#This Row],[6]]) -> 4.2561829 | I12: =(T_All_K1_N10_P0[[#This Row],[8]]-T_All_K1_N10_P0[[#This Row],[7]])/ABS(T_All_K1_N10_P0[[#This Row],[7]]) -> -0.81029855 | K12: =AVERAGE(B12:I12) -> 0.4324712 | L12: =(T_All_K1_N10_P0[[#This Row],[8]]-T_All_K1_N10_P0[[#This Row],[0]])/ABS(T_All_K1_N10_P0[[#This Row],[0]]) -> -0.41886478
A13: =T_All_K1_N10_P0[[#This Row],[Identifier]] -> f3cc524e5f2cc476c53eea535c2fc45073cef06fbd25ecd7e5fe92d8b87b3d29 | B13: =(T_All_K1_N10_P0[[#This Row],[1]]-T_All_K1_N10_P0[[#This Row],[0]])/ABS(T_All_K1_N10_P0[[#This Row],[0]]) -> 0.20377591 | C13: =(T_All_K1_N10_P0[[#This Row],[2]]-T_All_K1_N10_P0[[#This Row],[1]])/ABS(T_All_K1_N10_P0[[#This Row],[1]]) -> -0.35882979 | D13: =(T_All_K1_N10_P0[[#This Row],[3]]-T_All_K1_N10_P0[[#This Row],[2]])/ABS(T_All_K1_N10_P0[[#This Row],[2]]) -> 1.0180448 | E13: =(T_All_K1_N10_P0[[#This Row],[4]]-T_All_K1_N10_P0[[#This Row],[3]])/ABS(T_All_K1_N10_P0[[#This Row],[3]]) -> 0.066399081 | F13: =(T_All_K1_N10_P0[[#This Row],[5]]-T_All_K1_N10_P0[[#This Row],[4]])/ABS(T_All_K1_N10_P0[[#This Row],[4]]) -> -0.36975882 | G13: =(T_All_K1_N10_P0[[#This Row],[6]]-T_All_K1_N10_P0[[#This Row],[5]])/ABS(T_All_K1_N10_P0[[#This Row],[5]]) -> -0.65043734 | H13: =(T_All_K1_N10_P0[[#This Row],[7]]-T_All_K1_N10_P0[[#This Row],[6]])/ABS(T_All_K1_N10_P0[[#This Row],[6]]) -> 1.8147914 | I13: =(T_All_K1_N10_P0[[#This Row],[8]]-T_All_K1_N10_P0[[#This Row],[7]])/ABS(T_All_K1_N10_P0[[#This Row],[7]]) -> -0.24837799 | K13: =AVERAGE(B13:I13) -> 0.1844509 | L13: =(T_All_K1_N10_P0[[#This Row],[8]]-T_All_K1_N10_P0[[#This Row],[0]])/ABS(T_All_K1_N10_P0[[#This Row],[0]]) -> -0.22581088
J16: Average | K16: =AVERAGE(K2:K13) -> 0.13192922 | L16: =AVERAGE(L2:L13) -> -0.12700399
B19: 0-1 | C19: 1-2 | D19: 2-3 | E19: 3-4 | F19: 4-5 | G19: 5-6 | H19: 6-7 | I19: 7-8 | K19: Average | L19: Max-Min
A20: Average per Timestep | B20: =AVERAGE(B2:B13) -> 0.043681282 | C20: =AVERAGE(C2:C13) -> 0.37065161 | D20: =AVERAGE(D2:D13) -> 0.011312105 | E20: =AVERAGE(E2:E13) -> 0.18702069 | F20: =AVERAGE(F2:F13) -> -0.067090067 | G20: =AVERAGE(G2:G13) -> 0.024767231 | H20: =AVERAGE(H2:H13) -> 0.68226441 | I20: =AVERAGE(I2:I13) -> -0.19717348 | K20: =AVERAGE(B20:I20) -> 0.13192922 | L20: =('Relative Change'!I20-B20)/(ABS(B20)) -> -5.5139124

Sheet Graphs
A1: Pure Data
A2: Identifier | B2: 0 | C2: 1 | D2: 2 | E2: 3 | F2: 4 | G2: 5 | H2: 6 | I2: 7 | J2: 8 | K2: Column11 | L2: Column12
A3: 428da1312b4e9e175c8da20472e82f346f19060102702e896cd2ed510d1f82d3 | B3: 5.6707541 | C3: 2.6827083 | D3: 9.5101161 | E3: 4.1070766 | F3: 5.6419097 | G3: 4.972741 | H3: 5.3640856 | I3: 8.9479246 | J3: 7.0236156
A4: b96c0907522c2773f70c3772a20a66ed27faa11b69222bb914593d8c048e550f | B4: 7.8374335 | C4: 5.10084 | D4: 9.1046567 | E4: 4.3203477 | F4: 10.848992 | G4: 7.9346083 | H4: 5.4931447 | I4: 9.8119269 | J4: 5.5981144
A5: 91c19dd683a61988ab47f9523ac0c69189fc5bf0bc129535df465e67ceaa3f5c | B5: 6.4185382 | C5: 8.1532212 | D5: 7.9959563 | E5: 10.156819 | F5: 6.7149246 | G5: 6.3503785 | H5: 10.048271 | I5: 7.9475027 | J5: 6.9061622
A6: a77913344f83d12ba672562908a45473f0d39decfb73132ce324137df5880dca | B6: 3.6806851 | C6: 3.4622552 | D6: 7.1898996 | E6: 4.8316995 | F6: 3.4472675 | G6: 3.5914728 | H6: 7.3375266 | I6: 3.6664365 | J6: 1.5938415
A7: 31dc9a7ab1e4d4612bdaf0e2738743d8249dd2a8c694e94911c68de321218e14 | B7: 3.5151637 | C7: 4.4862471 | D7: 1.4861697 | E7: 1.3635102 | F7: 3.5352609 | G7: 3.5224217 | H7: 2.851021 | I7: 2.298538 | J7: 4.3910211
A8: cc16d76232e5a5ec88990779fb25161754f2fcae1be1817d9b06db6ed01a0252 | B8: 4.9728168 | C8: 3.8049531 | D8: 7.6249441 | E8: 7.713015 | F8: 6.2291926 | G8: 4.9568516 | H8: 7.0137946 | I8: 9.9947308 | J8: 3.6880669
A9: 6495f98496f9faa9acbcdcf4e6d7f54f0fc9d6989ccd6cbe8d514c709be1ae47 | B9: 7.4614274 | C9: 10.923784 | D9: 7.1545811 | E9: 9.045002 | F9: 4.1600031 | G9: 8.0067124 | H9: 4.6851752 | I9: 7.2636943 | J9: 4.8217605
A10: a0a4a0a999bb3c4c42ab65d8be5cc30bd395809ee6deffe8ff8849786856012c | B10: 13.601155 | C10: 12.48528 | D10: 8.0971608 | E10: 9.1003597 | F10: 9.6579612 | G10: 7.589509 | H10: 7.7401406 | I10: 8.0109913 | J10: 9.7207106
A11: 7f3b0e32ea2b17f7a0962be43fa129208723a474d1511b5ff8a21ed8c63aca65 | B11: 5.0645134 | C11: 4.9437104 | D11: 7.8400076 | E11: 9.0140865 | F11: 6.4631927 | G11: 5.7475034 | H11: 6.3928428 | I11: 3.9129451 | J11: 3.7021908
A12: 6f5b156caaebfa4130a64c596e5794c2e55be72403d2ceb5c236b43d6cf082d1 | B12: 3.5935725 | C12: 2.6608128 | D12: 3.2408391 | E12: 4.0361444 | F12: 4.4091368 | G12: 2.921721 | H12: 3.1326036 | I12: 6.0853784 | J12: 5.6636188
A13: 6aa02f42db10b522f763f840e9e8a0bcb461f6f2f570d596a768a59dbfd88113 | B13: 2.9964524 | C13: 5.5302329 | D13: 5.4020733 | E13: 3.0076945 | F13: 3.5713605 | G13: 3.2493069 | H13: 1.746399 | I13: 9.1793924 | J13: 1.741344
A14: f3cc524e5f2cc476c53eea535c2fc45073cef06fbd25ecd7e5fe92d8b87b3d29 | B14: 4.0426867 | C14: 4.8664889 | D14: 3.1202477 | E14: 6.2967995 | F14: 6.7149012 | G14: 4.2320073 | H14: 1.4793517 | I14: 4.1640665 | J14: 3.1298041
A29: R Squared
A30: Identifier | B30: R Squared
A31: ='R Squared'!A2 -> 428da1312b4e9e175c8da20472e82f346f19060102702e896cd2ed510d1f82d3 | B31: ='R Squared'!L2 -> 0.12240314
A32: ='R Squared'!A3 -> b96c0907522c2773f70c3772a20a66ed27faa11b69222bb914593d8c048e550f | B32: ='R Squared'!L3 -> 0.00095834561
A33: ='R Squared'!A4 -> 91c19dd683a61988ab47f9523ac0c69189fc5bf0bc129535df465e67ceaa3f5c | B33: ='R Squared'!L4 -> 0.0026480824
A34: ='R Squared'!A5 -> a77913344f83d12ba672562908a45473f0d39decfb73132ce324137df5880dca | B34: ='R Squared'!L5 -> 0.045007168
A35: ='R Squared'!A6 -> 31dc9a7ab1e4d4612bdaf0e2738743d8249dd2a8c694e94911c68de321218e14 | B35: ='R Squared'!L6 -> 0.0053449103
A36: ='R Squared'!A7 -> cc16d76232e5a5ec88990779fb25161754f2fcae1be1817d9b06db6ed01a0252 | B36: ='R Squared'!L7 -> 0.043188611
A37: ='R Squared'!A8 -> 6495f98496f9faa9acbcdcf4e6d7f54f0fc9d6989ccd6cbe8d514c709be1ae47 | B37: ='R Squared'!L8 -> 0.32325944
A38: ='R Squared'!A9 -> a0a4a0a999bb3c4c42ab65d8be5cc30bd395809ee6deffe8ff8849786856012c | B38: ='R Squared'!L9 -> 0.43918803
A39: ='R Squared'!A10 -> 7f3b0e32ea2b17f7a0962be43fa129208723a474d1511b5ff8a21ed8c63aca65 | B39: ='R Squared'!L10 -> 0.14743669
A40: ='R Squared'!A11 -> 6f5b156caaebfa4130a64c596e5794c2e55be72403d2ceb5c236b43d6cf082d1 | B40: ='R Squared'!L11 -> 0.42154895
A41: ='R Squared'!A12 -> 6aa02f42db10b522f763f840e9e8a0bcb461f6f2f570d596a768a59dbfd88113 | B41: ='R Squared'!L12 -> 0.00049423108
A42: ='R Squared'!A13 -> f3cc524e5f2cc476c53eea535c2fc45073cef06fbd25ecd7e5fe92d8b87b3d29 | B42: ='R Squared'!L13 -> 0.098353899
A43: ='R Squared'!K16 -> Ave RSQ | B43: ='R Squared'!L16 -> 0.13748596
A59: Relative Change
A60: ='Relative Change'!A1 -> ID | B60: Change
A61: ='Relative Change'!A2 -> 428da1312b4e9e175c8da20472e82f346f19060102702e896cd2ed510d1f82d3 | B61: ='Relative Change'!K2 -> 0.27959586
A62: ='Relative Change'!A3 -> b96c0907522c2773f70c3772a20a66ed27faa11b69222bb914593d8c048e550f | B62: ='Relative Change'!K3 -> 0.15023096
A63: ='Relative Change'!A4 -> 91c19dd683a61988ab47f9523ac0c69189fc5bf0bc129535df465e67ceaa3f5c | B63: ='Relative Change'!K4 -> 0.046283564
A64: ='Relative Change'!A5 -> a77913344f83d12ba672562908a45473f0d39decfb73132ce324137df5880dca | B64: ='Relative Change'!K5 -> 0.052756918
A65: ='Relative Change'!A6 -> 31dc9a7ab1e4d4612bdaf0e2738743d8249dd2a8c694e94911c68de321218e14 | B65: ='Relative Change'!K6 -> 0.20501109
A66: ='Relative Change'!A7 -> cc16d76232e5a5ec88990779fb25161754f2fcae1be1817d9b06db6ed01a0252 | B66: ='Relative Change'!K7 -> 0.074125083
A67: ='Relative Change'!A8 -> 6495f98496f9faa9acbcdcf4e6d7f54f0fc9d6989ccd6cbe8d514c709be1ae47 | B67: ='Relative Change'!K8 -> 0.0708944
A68: ='Relative Change'!A9 -> a0a4a0a999bb3c4c42ab65d8be5cc30bd395809ee6deffe8ff8849786856012c | B68: ='Relative Change'!K9 -> -0.024280888
A69: ='Relative Change'!A10 -> 7f3b0e32ea2b17f7a0962be43fa129208723a474d1511b5ff8a21ed8c63aca65 | B69: ='Relative Change'!K10 -> -0.0014328502
...
